Workbook

Sheet Contrato
G2: CONTRATO DE MATRÍCULA
G3: GESTIÓN ADMINISTRATIVA Y FINANCIERA
G5: Código: GOT-DOC-01 | J5: Versión:03 | M5: Vigencia: 31/12/21 | Q5: Página: 1 de 4
B7: FOTOGRAFÍA 3 x 4 | F7: Unicab Corporación Educativa "Colegio UNICAB Virtual" | R7: FECHA
F8: EDUCACIÓN BÁSICA PRIMARIA, BÁSICA SECUNDARIA Y MEDIA ACADÉMICA | R8: Día | S8: Mes | T8: Año
F9: Resolución 061 de 15 de Diciembre de 2007 S.E. y Cultura de Sogamoso
F10: Resolución 0155 de 21 de julio de 2010 - Resolución 326 de 22 de septiembre de 2015
F12: VALOR MATRÍCULA | L12: ANUAL PENSIÓN
F13: ESTADO DE | G13: ESTUDIANTE NUEVO | J13: HOMOLOGACIÓN | M13: CONVALIDACIÓN | R13: RENOVACIÓN
F14: MATRÍCULA | G14: UNIDAD A LA QUE INGRESA | J14: PRIMARIA | M14: SECUNDARIA | R14: M. ACADÉMICA
F15: GRADO AL QUE INGRESA | M15: CICLO DE INGRESO
F16: TIPO DE | G16: CONTADO | H16: ACUERDO | J16: CONVENIO | R16: No. CONTRATO - FICHA
F17: MATRÍCULA
B19: NOMBRE DEL
B20: ESTUDIANTE
B21: DOCUMENTO | C21: T.I | D21: C.C | E21: C.E | F21: NÚMERO DE DOCUMENTO | I21: LUGAR Y FECHA DE NACIMIENTO | O21: Día | P21: Mes | R21: Año | T21: SEXO
B22: DE IDENTIDAD
B23: DIRECCIÓN | K23: CIUDAD/DEPTO.
B24: ÚLTIMO | O24: ÚLTIMO GRADO
B25: COLEGIO | O25: APROBADO
B26: ESTADO CIVIL | J26: EDAD | O26: ESTRATO
B27: TELÉFONOS | K27: EMAIL
B28: CONDICIÓN | K28: TIEMPO QUE DEDICA
B29: SOCIOECONÓMICA
B30: ACREDITADA
B31: DISCAPACIDAD | C31: NINGUNA | F31: FÍSICA | G31: COGNITIVA | H31: AUDITIVA | J31: VISUAL | K31: MENTAL | M31: OTRA | N31: DE EXISTIR, POR FAVOR ESPECIFIQUE CUÁL ES LA INCAPAIDAD
B34: NOMBRE DEL
B35: Acudiente
B36: DOCUMENTO | I36: DIRECCIÓN DE RESIDENCIA | Q36: TELÉFONOS
B37: DE IDENTIDAD | C37: EXPEDIDA EN.
B38: PROFESIÓN | J38: EMPRESA
B39: TELÉFONO | J39: EMAIL
B41: NOMBRE DEL
B42: PADRE
B43: DOCUMENTO | I43: DIRECCIÓN DE RESIDENCIA | Q43: TELÉFONOS
B44: DE IDENTIDAD | C44: EXPEDIDA EN.
B45: PROFESIÓN | J45: EMPRESA
B46: TELÉFONO | J46: EMAIL
B48: NOMBRE DE
B49: LA MADRE
...

Sheet Pagare
G2: CONTRATO DE MATRÍCULA
G3: GESTIÓN ADMINISTRATIVA Y FINANCIERA
G5: Código: GOT-DOC-01 | J5: Versión:03 | M5: Vigencia: 31/12/21 | Q5: Página: 1 de 2
C7: DATOS IDENTIFICADORES DEL PAGARÉ | R7: FECHA SUSCRIPCIÓN
C8: POR CONTRATO DE MATRÍCULA Y PENSIÓN | R8: Día | S8: Mes | T8: Año
G9: PAGARÉ No. | J9: =+Contrato!R17 -> 0 | R9: =+Contrato!R9 -> 0 | S9: =+Contrato!S9 -> 0 | T9: =+Contrato!T9 -> 0
B11: No. CONTRATO | D11: =+Contrato!R17 -> 0 | H11: FECHA CONTRARO | K11: =CONCATENATE(Contrato!T9,"/",Contrato!S9,"/",Contrato!R9) -> // | O11: VALOR TOTAL
B12: VALOR EN LETRAS
B13: DESCRIMINACIÓN | D13: CONCEPTO MATRÍCULA | H13: OTROS COSTOS | K13: VALOR PENSIÓN | P13: NO. MENSUALIDADES
B14: DEL PAGO
B16: NOMBRE DEL | C16: =+Contrato!C34 -> 0
B17: DEUDOR
B18: DOCUMENTO | C18: =+Contrato!C36 -> 0 | I18: DIRECCIÓN DE RESIDENCIA | Q18: TELÉFONOS
B19: DE IDENTIDAD | C19: EXPEDIDA EN. | F19: =IF(Contrato!F37="","",Contrato!F37) | I19: =IF(Contrato!I37="","",Contrato!I37) | Q19: =IF(Contrato!Q37="","",Contrato!Q37)
B20: PROFESIÓN | C20: =IF(Contrato!C38="","",Contrato!C38) | J20: EMPRESA | K20: =IF(Contrato!K38="","",Contrato!K38)
B21: TELÉFONO | C21: =IF(Contrato!C39="","",Contrato!C39) | J21: EMAIL | K21: =IF(Contrato!K39="","",Contrato!K39)
B22: ESTUDIANTE | C22: =IF(Contrato!C19="","",Contrato!C19) | J22: DOCUMENTO | K22: =IF(Contrato!F22="","",Contrato!F22) | Q22: GRADO | S22: =IF(Contrato!H15="","",Contrato!H15)
B24: DATOS DEL | C24: Unidad de Capacitación Empresarial de Boyacá "UNICAB Corporación Educativa" administradora colegio UNICAB virtual | P24: NIT | R24: 826.002.762-1
B25: ACREEDOR
B26: REPRESENTANTE | C26: IMELDA VERGARA GÓMEZ | K26: CÉDULA | O26: 46.352.777 de Sogamoso
B27: TELÉFONO | C27: 318 714 3774 | J27: E- MAIL | K27: cartera@unicab.org
A29: CARTA DE INSTRUCCIONES
B31: Por medio el presente, el denominado DEUDOR, descrito en los datos identificadores del presente documento, manifiesto mi voluntad libre y espontánea de suscribir el
B32: presente Pagaré que garantiza el pago de la matricula, pensiones y otros costos académicos correspondientes al servicio educativo del año lectivo de | T32: =+Contrato!P108 -> 0 | V32: ,
B33: contratado con el Colegio UNICAB Virtual.
B35: Por consiguiente, en calidad de acudiente / padre de familia, declaro que soy mayor de edad, me identifico como aparece al pie de mi firma, que obro en nombre propio
B36: como representante y/o benefactor del estudiante de la referencia, manifiesto que gozo de capacidad legal para celebrar este contrato y suscribir este título valor, que
B37: establece de manera clara, expresa y por consiguiente exigible que debo y pagaré, incondicional y solidariamente a la orden del ACREEDOR de la referencia o a la
B38: persona natural o jurídica a quien el mencionado acreedor ceda o endose sus derechos sobre este pagaré, la suma cierta en moneda legal colombiana y además:
B40: PRIMERO. OBJETO: Que en virtud del presente título valor EL DEUDOR se compromete a pagar incondicionalmente a la orden del ACREEDOR, la suma estipulada,
B41: que dicho valor corresponde al valor total de la matricula, los cánones de pensión y la suma referida como otros costos por concepto de la prestación del servicio
B42: educativo del beneficiario, descrito en el cuadro de la referencia, que el domicilio contractual del presente pagaré es la ciudad de Sogamoso Boyacá, país Colombia.
B44: SEGUNDO: FORMAS DE PAGO. Que la suma expresada, será cancela en un pago inicial por concepto de matrícula, un pago posterior por concepto de costos
B45: académicos y | C45: =+Contrato!F126 -> 0 | F45: pagos mensuales correspondientes al concepto de pensión, durante los diez (10) primeros días de cada mes, comenzando desde el
B46: =CONCATENATE(Contrato!K108," de ",Contrato!M108," de ",Contrato!P108) -> de de | F46: terminando en el año académico, en los canales de pago establecidos por el colegio. Los pagos atrasados y sus respectivos intereses
B47: podrán hacerse en el Banco Caja Social al número de cuenta Corriente No. 21003786216 Titular UNICAB Corporación Educativa en formato de consignación
B48: Comprobante Universal de Recaudo, o en las oficinas del colegio ubicadas en Calle 13ª 16 - 60 Sogamoso (Boyacá); en BANCO AV VILLAS CUENTA CORRIENTE No.
B49: 72017457–2 TITULAR: UNICAB CORPORACIÓN EDUCATIVA, y por los canales de pago en línea Epayco según instructivo en la página
B50: https://unicab.org/pagos_payservices.php
B52: TERCERO: INTERÉS POR MORA. En caso de mora reconoceré intereses en favor del ACREEDOR el porcentaje establecido al máximo legal bancario vigente a la mas
...

Sheet Colores
A1: 42 86 138 | B1: #2A568A | Z1: F
Z2: M
A3: 74 135 209 | B3: #4A87D1
A5: 219 228 240 | B5: #DBE4F0
A7: 182 221 232 | B7: #B6DDE8
A9: 217 217 217 | B9: #D9D9D9
